Workbook

Sheet Business Overview
A1: Business Overview
A3: Firm, regulatory, team, organisation and lead-source information in one place.
A5: Firm and Regulatory Information
A6: Firm name | B6: Duncan & Co Financial
A7: Previous firm / network | B7: Rettie Financial Services (5 years, FRN 969595); previously Simpson & Marwick, then one year in Aberdeen
A8: Business address | B8: 88 Bonaly Grove, Edinburgh, EH13 0QB
A9: FCA number | B9: TBC — Duncan & Co not yet set up (Rettie Financial Services was FRN 969595)
A10: MAB FCA number | B10: TBC / don't know
A11: L&G master agency number | B11: N/A — don't have one
A12: MAB agency number | B12: N/A — don't have one
A13: Pipeline novated? | B13: No — none novated (pipeline issues)
A14: Fee structure | B14: Standard purchase & remortgage: £195 on application, £300 on offer. Debt consolidation / adverse: £495 on application, £500 on offer. International: £495 on application, £1,000 on offer.
A15: Specialist licences required | B15: Mortgage and protection; bridging; buy-to-let and commercial (B&C)
A18: Team and Organisation
A19: Name | B19: Role | C19: Director / Key Individual | D19: Employed / SE | E19: Location | F19: Licences | G19: Admin / Case Manager | H19: GI Specialist
A20: Robert Duncan | B20: Director / Mortgage & Protection Adviser | C20: Yes | D20: Self-employed | E20: Edinburgh | F20: Mortgage, protection, bridging, BTL & commercial | G20: No (self at launch) | H20: No
A24: Lead-out and commercial split
A25: Duncan & Co can pass leads out to specialist advisers (bridging, commercial, BTL, overflow or other work the firm does not keep) for an agreed commercial split.
A26: Split terms | B26: 50/50 split. The customer remains a Duncan & Co Financial customer.
A34: Lead Sources
A35: Lead Source | B35: Transfer Method | C35: Introducer Type | D35: Monthly Volume | E35: Close Rate | F35: Owner / Notes
A36: DJ Alexander | B36: Email introduction (Edinburgh & Lothians) | C36: Estate agent | D36: 5–7 leads a month | E36: 1 in 3 conversion | F36: David Alexander
A37: Thorntons Solicitors | B37: Email introduction (Edinburgh & Lothians) | C37: Solicitor | D37: 3–7 leads a month | E37: 1 in 3 conversion | F37: Hannah Fraser
A38: TBC — system referral process | B38: System-related referral process | C38: Estate agent | D38: 10–20 leads a week (estimate) | E38: 1 in 3 conversion | F38: No notes
A39: Planning conversion model | B39: 40 leads → 30 spoken | C39: All sources combined | D39: 40 leads a month | E39: 1 in 3 of 30 spoken (10 completions) | F39: Drives Financial Plan written target

Sheet Executive Summary
A1: 2027 Strategic Business Plan
A3: A compact executive view of targets, priorities and delivery status.
A4: ='Financial Plan'!P16 | E4: =AVERAGE('Financial Plan'!D16:O16) | I4: =SUM('Financial Plan'!P13:P14) | M4: ='Financial Plan'!P15
A6: Annual written target | E6: Average monthly target | I6: Mortgage & Protection annual target | M6: Other Income annual target
A8: Quarterly written target
A9: Metric | B9: Q1 | C9: Q2 | D9: Q3 | E9: Q4 | F9: Annual
A10: Total | B10: ='Financial Plan'!B24 | C10: ='Financial Plan'!C24 | D10: ='Financial Plan'!D24 | E10: ='Financial Plan'!E24 | F10: ='Financial Plan'!F24
A11: Mortgage | B11: ='Financial Plan'!B21 | C11: ='Financial Plan'!C21 | D11: ='Financial Plan'!D21 | E11: ='Financial Plan'!E21 | F11: ='Financial Plan'!F21
A12: Protection | B12: ='Financial Plan'!B22 | C12: ='Financial Plan'!C22 | D12: ='Financial Plan'!D22 | E12: ='Financial Plan'!E22 | F12: ='Financial Plan'!F22
A13: Other Income | B13: ='Financial Plan'!B23 | C13: ='Financial Plan'!C23 | D13: ='Financial Plan'!D23 | E13: ='Financial Plan'!E23 | F13: ='Financial Plan'!F23
A16: Plan details
A17: Firm name | B17: Duncan & Co Financial
A18: Plan owner | B18: Robert Duncan
A19: Version date | B19: 46300
A20: Model status | B20: ='Risks & Actions'!B6
A24: Month | B24: Mortgage | C24: Protection | D24: Other Income | E24: Total
A25: Jan | B25: ='Financial Plan'!D13 | C25: ='Financial Plan'!D14 | D25: ='Financial Plan'!D15 | E25: ='Financial Plan'!D16
A26: Feb | B26: ='Financial Plan'!E13 | C26: ='Financial Plan'!E14 | D26: ='Financial Plan'!E15 | E26: ='Financial Plan'!E16
A27: Mar | B27: ='Financial Plan'!F13 | C27: ='Financial Plan'!F14 | D27: ='Financial Plan'!F15 | E27: ='Financial Plan'!F16
A28: Apr | B28: ='Financial Plan'!G13 | C28: ='Financial Plan'!G14 | D28: ='Financial Plan'!G15 | E28: ='Financial Plan'!G16
A29: May | B29: ='Financial Plan'!H13 | C29: ='Financial Plan'!H14 | D29: ='Financial Plan'!H15 | E29: ='Financial Plan'!H16
A30: Jun | B30: ='Financial Plan'!I13 | C30: ='Financial Plan'!I14 | D30: ='Financial Plan'!I15 | E30: ='Financial Plan'!I16
A31: Jul | B31: ='Financial Plan'!J13 | C31: ='Financial Plan'!J14 | D31: ='Financial Plan'!J15 | E31: ='Financial Plan'!J16
A32: Aug | B32: ='Financial Plan'!K13 | C32: ='Financial Plan'!K14 | D32: ='Financial Plan'!K15 | E32: ='Financial Plan'!K16
A33: Sep | B33: ='Financial Plan'!L13 | C33: ='Financial Plan'!L14 | D33: ='Financial Plan'!L15 | E33: ='Financial Plan'!L16
A34: Oct | B34: ='Financial Plan'!M13 | C34: ='Financial Plan'!M14 | D34: ='Financial Plan'!M15 | E34: ='Financial Plan'!M16
A35: Nov | B35: ='Financial Plan'!N13 | C35: ='Financial Plan'!N14 | D35: ='Financial Plan'!N15 | E35: ='Financial Plan'!N16
A36: Dec | B36: ='Financial Plan'!O13 | C36: ='Financial Plan'!O14 | D36: ='Financial Plan'!O15 | E36: ='Financial Plan'!O16

Sheet Financial Plan
A1: 2027 Financial Plan
A3: Three income streams only. Change yellow assumptions or overwrite yellow monthly cells for seasonality; totals update automatically.
A5: Core assumptions
A6: Income Stream | B6: Default Monthly Target | C6: Lag (months) | D6: Scope
A7: Mortgage | B7: =B33 | C7: 2 | D7: 40 leads → 30 spoken → 1 in 3 = 10 completions × £180k–£250k (mid £215k). Income = 0.35% of written. Change yellow cells in the conversion model below.
A8: Protection | B8: =B35 | C8: 2 | D8: £1,000 per protection case; 1 in 3 of the 10 completions ≈ 3 cases. Linked to the conversion model.
A9: Other Income | B9: 0 | C9: 0 | D9: GI, referrals and Beanstalk JISA starter — overwrite if needed
A11: Monthly written targets
A12: Income Stream | B12: Default Monthly | C12: Scope | D12: Jan | E12: Feb | F12: Mar | G12: Apr | H12: May | I12: Jun | J12: Jul | K12: Aug | L12: Sep | M12: Oct | N12: Nov | O12: Dec | P12: Annual
A13: Mortgage | B13: =B7 | C13: New Build and Retention | D13: =$B7 | E13: =$B7 | F13: =$B7 | G13: =$B7 | H13: =$B7 | I13: =$B7 | J13: =$B7 | K13: =$B7 | ... O13: =$B7 | P13: =SUM(D13:O13)
A14: Protection | B14: =B8 | C14: Protection income | D14: =$B8 | E14: =$B8 | F14: =$B8 | G14: =$B8 | H14: =$B8 | I14: =$B8 | J14: =$B8 | K14: =$B8 | ... O14: =$B8 | P14: =SUM(D14:O14)
A15: Other Income | B15: =B9 | C15: Wealth, GI, Later Life and referrals | D15: =$B9 | E15: =$B9 | F15: =$B9 | G15: =$B9 | H15: =$B9 | I15: =$B9 | J15: =$B9 | K15: =$B9 | ... O15: =$B9 | P15: =SUM(D15:O15)
A16: TOTAL | C16: All income streams | D16: =SUM(D13:D15) | E16: =SUM(E13:E15) | F16: =SUM(F13:F15) | G16: =SUM(G13:G15) | H16: =SUM(H13:H15) | I16: =SUM(I13:I15) | J16: =SUM(J13:J15) | K16: =SUM(K13:K15) | ... O16: =SUM(O13:O15) | P16: =SUM(D16:O16)
A19: Quarterly roll-up
A20: Stream | B20: Q1 | C20: Q2 | D20: Q3 | E20: Q4 | F20: Annual
A21: Mortgage | B21: =SUM(D13:F13) | C21: =SUM(G13:I13) | D21: =SUM(J13:L13) | E21: =SUM(M13:O13) | F21: =P13
A22: Protection | B22: =SUM(D14:F14) | C22: =SUM(G14:I14) | D22: =SUM(J14:L14) | E22: =SUM(M14:O14) | F22: =P14
A23: Other Income | B23: =SUM(D15:F15) | C23: =SUM(G15:I15) | D23: =SUM(J15:L15) | E23: =SUM(M15:O15) | F23: =P15
A24: Total | B24: =SUM(D16:F16) | C24: =SUM(G16:I16) | D24: =SUM(J16:L16) | E24: =SUM(M16:O16) | F24: =P16
A26: Conversion model (plan target)
A27: Driver | B27: Value | C27: Unit / note
A28: Leads in a month | B28: 40 | C28: Inbound leads
A29: Spoken with | B29: 30 | C29: Appointments / conversations from those leads
A30: Conversion of spoken (1 in n) | B30: 3 | C30: 1 in 3 of the 30 spoken
A31: Completions | B31: =B29/B30 | C31: Spoken ÷ conversion = 10 cases
A32: Average loan (mid of £180k–£250k) | B32: 215000 | C32: Overwrite if you want low £180k or high £250k
A33: Mortgage written (feeds B7) | B33: =B31*B32 | C33: 10 × average loan
A34: Mortgage income at 0.35% (before network) | B34: =B33*0.0035 | C34: Not banked cash until the 2-month lag
A35: Protection cases (1 in 3 completions × £1,000) | B35: =ROUND(B31/3,0)*1000 | C35: About 3 cases → £3,000 (feeds B8)

Sheet Monthly Costs
A1: Monthly Costs — Bob Duncan / Duncan & Co Financial
A3: Yellow cells are editable. Confirmed network terms are from the 2 Sep 2026 Rosemount meeting (Ahmed Bawa). Do not treat Financial Plan protection written (£240,000/month) as cash. Tesla lease, website and most operating lines are estimates for Bob to overwrite.
A5: 1. Confirmed network terms (Rosemount / Rosemount Financial Solutions)
A6: Item | B6: Value | C6: Status | D6: Source / notes | E6: Linked calculation
A7: Weekly Rosemount fee | B7: 75 | C7: Confirmed | D7: £75/week covers FCA, PI and software (2 Sep 2026). | E7: Confirmed commercial term
A8: Weeks per year (for monthly conversion) | B8: 52 | C8: Confirmed | D8: Standard 52-week year. | E8: Used in monthly fee formula
A9: Monthly Rosemount fee | B9: =$B$7*$B$8/12 | C9: Formula | D9: 75 × 52 / 12. Confirmed from weekly term. | E9: 75*52/12
A10: Mortgage net retention (network share) | B10: 0.1 | C10: Confirmed | D10: Bob keeps 90% of mortgage procuration. | E10: 10% net retention mortgages
A11: Protection net retention (network share) | B11: 0.15 | C11: Confirmed | D11: Bob keeps 85% of protection commission. | E11: 15% net retention protection
A12: Mortgage procuration fee % | B12: 0.0035 | C12: Confirmed | D12: Robert Duncan: mortgage income is 0.35% of borrowing. Typical loan £180k–£250k. | E12: Used in cash bridge
A13: Protection cash commission (monthly, before retention) | B13: ='Financial Plan'!B8 | C13: Linked | D13: £1,000 × ~3 protection cases from 10 completions (1 in 3). Linked to conversion model. | E13: Used in cash bridge
A14: Year-1 income ambition (low) | B14: 80000 | C14: Discussed | D14: 20 Aug 2026 structure consult. | E14: Ambition range
A15: Year-1 income ambition (high) | B15: 120000 | C15: Discussed | D15: 20 Aug 2026 structure consult. | E15: Ambition range
A16: Financial Plan mortgage / protection lag (months) | B16: ='Financial Plan'!C7 | C16: Linked | D16: Written work banks on a lag. Used in the 12-month cash view. | E16: Financial Plan C7
A18: 2. Monthly operating costs
A19: Cost item | B19: Monthly £ | C19: Type | D19: Status | E19: Notes | F19: Annual £
A20: Rosemount network fee | B20: =$B$9 | C20: Fixed | D20: Confirmed | E20: From weekly £75 term (FCA, PI, software). | F20: =B20*12
A21: Tesla Model Y lease | B21: 0 | C21: Fixed | D21: Confirmed | E21: Tesla Model Y is in Robert’s personal name — not a business cost. | F21: =B21*12
A22: EV insurance | B22: 0 | C22: Fixed | D22: Ignored | E22: Ignored — not a business cost for this plan. | F22: =B22*12
A23: Home / destination charging | B23: 0 | C23: Variable | D23: Ignored | E23: Ignored — not a business cost for this plan. | F23: =B23*12
A24: Mobile phone | B24: 45 | C24: Fixed | D24: Confirmed | E24: £45/month — confirmed by Robert. | F24: =B24*12
A25: Broadband share | B25: 30 | C25: Fixed | D25: Confirmed | E25: £30 home-office share — left as is by Robert. | F25: =B25*12
A26: Office subscription | B26: 30 | C26: Fixed | D26: Confirmed | E26: Office subscription (Robert). | F26: =B26*12
A27: Xero | B27: 33 | C27: Fixed | D27: Confirmed | E27: £33/month Xero — confirmed by Robert. | F27: =B27*12
A28: Accountant | B28: 150 | C28: Fixed | D28: Confirmed | E28: £150/month accrual — confirmed by Robert. | F28: =B28*12
A29: Domain name and website | B29: 14.99 | C29: Fixed | D29: Confirmed | E29: Domain name and website together. | F29: =B29*12
A30: Web hosting (included above) | B30: 0 | C30: Fixed | D30: Confirmed | E30: Included in the £14.99 domain/website line. | F30: =B30*12
A31: AI package | B31: 72 | C31: Variable | D31: Confirmed | E31: AI package (Robert). | F31: =B31*12
A32: Marketing / PPC / print | B32: 0 | C32: Variable | D32: Confirmed | E32: Set to £0 by Robert. | F32: =B32*12
... A37: Contingency | B37: 100 | C37: Variable | D37: Estimate | E37: Buffer for forgotten small costs. | F37: =B37*12
A38: TOTAL monthly operating costs | B38: =SUM(B20:B37) | E38: Updates when any yellow monthly amount changes. | F38: =B38*12
A40: 3. One-off launch costs (not in the monthly run-rate)
A41: Item | B41: Amount £ | C41: Type | D41: Status | E41: Notes | F41: In 12-month cash view?
A42: Laptop | B42: 0 | C42: One-off | D42: Moved | E42: Laptop is £50/month in operating costs, not a one-off. | F42: Jan cash outflow
A43: Website build | B43: 0 | C43: One-off | D43: Included | E43: Website is in the £14.99 monthly domain/website line. | F43: Jan cash outflow
A44: Company formation | B44: 480 | C44: One-off | D44: Confirmed | E44: £400 + VAT for business registration and setup. | F44: Jan cash outflow
A45: Branding / ID / cards | C45: One-off | D45: TBC | E45: Leave blank until quoted. | F45: Jan cash outflow if entered
A46: TOTAL one-off launch costs | B46: =SUM(B42:B45) | E46: Website may be grant-funded — overwrite B43 to 0 if so. | F46: =B46
A48: 4. Cash income bridge (steady-state month — written is not cash)
A49: Line | B49: Monthly £ | C49: Annual £ | D49: Notes | E49: Formula / source
...

Sheet Quarterly Planner
A1: 2027 Quarterly Planner
A3: Duncan & Co launch year. Keep actions compact. Yellow cells stay editable.
A5: Annual goals | C5: Q1 — Jan to Mar 2027 (plus residual 2026 launch) | E5: Q2 — Apr to Jun 2027
A6: Appoint with Rosemount as trading style and launch Duncan & Co (own brand retained) | C6: Finish refs, tests and DD; confirm Rosemount appointment (target end Sep 2026 if still open) | E6: Review Q1 written vs cash (2-month banking lag)
A7: Deliver conversion model: 40 leads → 30 spoken → 10 completions; mortgage written from Financial Plan | C7: Sign working SLAs with DJ Alexander and Hannah Fraser | E7: Close or park Ralph’s Thayer (Ivan Ralph) outreach
A8: Build toward £80–120k year-1 cash after 10% / 15% network retention — see Monthly Costs | C8: Website live or Business Gateway grant outcome recorded | E8: Measure protection attachment on completions
A9: Run DJ Alexander and Thorntons as live introducers; system source TBC toward the 40-lead month | C9: Intelligent Office + Mortgage Brain live; write the client journey | E9: Accountant introduction route live via self-employed cases
A10: Stand up website (Business Gateway grant) and Intelligent Office client journey | C10: Attend Rosemount protection workshops; start Beanstalk JISA partnership | E10: Glasgow exclusive: confirm in writing or treat as parked / high risk
A11: Decide AR vs trading-style only if the Glasgow exclusive actually lands
C13: Q3 — Jul to Sep 2027 | E13: Q4 — Oct to Dec 2027
C14: Mid-year cash vs £80–120k ambition using Monthly Costs | E14: Close remaining mortgage and protection written gaps
C15: AR decision if Glasgow volume is real enough for extra advisers | E15: 2028 plan: sole trader vs limited company; wife as possible shareholder
C16: International advice: Rosemount permission granted or stay refer-only | E16: Tesla lease amount confirmed; company-transfer decision with lessor
C17: BoE hold / cut / rise CRM cadence proven in Intelligent Office | E17: Annual introducer reviews (DJ Alexander, Hannah Fraser, others)
C18: Add a case manager only if sole-adviser capacity breaks | E18: Hold annual planning review and lock 2028 budget
A20: Informed by: 20 Aug 2026 structure consult; 2 Sep Rosemount (Ahmed Bawa); 2 Sep Ivan Ralph outreach; 3 Sep Business Gateway; 26 Aug rate-email / Tribe compliance notes.

Sheet Strategy Plan
A1: Consolidated Strategy Plan
A3: All strategic-planning subjects are retained in one editable table.
A5: Workstream | B5: Current Position | C5: 2027 Objective | D5: Key Actions / Operating Model | E5: KPI / Target | F5: Owner | G5: Quarter | H5: Status | I5: Planning Prompts
A6: Objectives | B6: New firm after redundancy from Rettie (protected conversation Aug 2026). No client bank. Year-1 cash ambition £80–120k. | C6: Launch Duncan & Co; hit the 40 / 30 / 1-in-3 conversion model (10 completions; written from Financial Plan) and build year-1 cash. | D6: Complete Rosemount appointment; lock introducers; run an activity-first first year; review AR only if Glasgow lands. | E6: £12.42m mortgage / £2.88m protection written; £80–120k cash | F6: Bob | G6: All Year | H6: In Progress | I6: 12-month vision; turnover and banked targets; adviser growth; productivity; written-to-banked conversion; customer journey and KPIs.
A7: Recruitment | B7: Solo launch. Later AR status only if advisers are recruited (needed for Glasgow-scale volume). | C7: Stay solo unless an exclusive Glasgow introducer is signed (that path could support 3–4 advisers). | D7: Do not hire until volume is confirmed in writing; agree AR transition steps with Rosemount if it lands. | E7: Adviser count = 1 unless Glasgow exclusive signed | F7: Bob | G7: Q3 | H7: Not Started | I7: Current adviser levels and locations; employed/self-employed model; contracts and packages; academy options; recruitment activity and resources.
A8: Lead Generation | B8: DJ Alexander primary Edinburgh & Glasgow; Hannah Fraser agreed primary Edinburgh solicitor/property; Ivan Ralph outreach started; Glasgow agency unconfirmed. | C8: Diversify so no single introducer dominates; add website, accountants and BoE CRM. | D8: Formalise DJ Alexander and Hannah Fraser; follow up Ivan Ralph; Business Gateway website; BoE rate emails. | E8: Live introducer SLAs; volume/close rates in Overview (yellow TBC) | F8: Bob | G8: Q1 | H8: In Progress | I8: Current and new lead sources; introducers; digital tools; volume and value by stream; ownership and support.
A9: Protection | B9: Protection at £1,000 a case; 1 in 3 of mortgage completions. Network 15% retention. | C9: High attachment on every mortgage; attend workshops; use Solution Builder / UnderwriteMe / iPipeline. | D9: Build protection into the client journey; track attachment % on the KPI Tracker. | E9: £240k/month written; cash via Monthly Costs £3,000 assumption | F9: Bob | G9: All Year | H9: Not Started | I9: Current mix and penetration; sales/referral model; triggers; commission splits; SLAs; development; client-bank campaigns; benchmark actions.
A10: GI | B10: No GI book. Other Income set to £0 for 2027 until a route is agreed. | C10: Establish a GI referral route and switch on the Beanstalk JISA partnership. | D10: Confirm GI panel/referral with Rosemount; set an offer-stage trigger. | E10: £1,500/month Other Income starter | F10: Bob | G10: Q2 | H10: Not Started | I10: Current and target GI penetration; specialist/referral model; triggers; VITA options; commission splits; SLAs; development opportunities.
A11: Client Bank | B11: No personal client bank; pipeline not novated from Rettie / Carrington. | C11: Build a new bank from introducer completions in Intelligent Office. | D11: IO CRM setup; BoE hold/cut/rise emails; annual-review process from first completions. | E11: PED retention and review % once a book exists | F11: Bob | G11: Q2 | H11: Not Started | I11: Client nurture; PED management and retention; annual reviews; OOCB reports/campaigns; communications; specialist support; KPIs and conversion.
A12: Admin & Leads | B12: Self-admin at launch. Tools: Intelligent Office, Mortgage Brain, Solution Builder / UnderwriteMe / iPipeline. | C12: Tight SLAs as sole adviser; add a case manager only if volume requires it. | D12: Document the client journey; keep IO pipeline clean; keep the Overview hire rows as TBC. | E12: Response SLA; completion time; quality | F12: Bob | G12: Q1 | H12: Not Started | I12: Admin/case-manager resources and roles; workflow; lead management; nurture and qualification; overdue reviews; SLAs and incentives.
A13: Marketing | B13: duncanandcofinancial.co.uk not yet built. Business Gateway funding discussed 3 Sep 2026. | C13: Live site + light PPC + rate-triggered CRM emails. | D13: Contact Business Gateway; set brand; load the three BoE scenario emails drafted 26 Aug. | E13: Website/PPC leads; cost per lead | F13: Bob | G13: Q1 | H13: In Progress | I13: Website/social audit; profile and lead generation support; ownership; PPC and campaigns; onboarding; Dashley/Mortgage Monitoring; digital toolkit.
A14: Wealth & Later Life | B14: Later-life / equity release TBC with Rosemount. International/overseas buyers still need compliance agreement. | C14: Confirm permissions before any later-life or international advice; refer if not approved. | D14: Agree later-life and international rules with Rosemount before the first case. | E14: Zero unapproved advice; referral log if needed | F14: Bob | G14: Q2 | H14: Not Started | I14: New/existing client opportunities; referral process and ownership; development and training; readiness milestones; interim referral approach.
A15: Other Income | B15: Starter £1,500/month. Beanstalk JISA partnership available via Rosemount. | C15: Other Income held at £0 unless a GI / referral route is switched on. | D15: Beanstalk onboarding; accountant intros via self-employed cases; conveyancing/wills only if a panel exists. | E15: £1,500/month default (Financial Plan yellow) | F15: Bob | G15: Q2 | H15: Not Started | I15: Moving Hub; conveyancing; wills; Wealth; GI; Later Life; bridging/commercial referrals; providers; ownership; SLAs and income targets.

Sheet KPI Tracker
A1: 2027 KPI Tracker
A3: Targets link to the Financial Plan. Enter actuals and operating percentages in yellow cells.
A5: Month | B5: Total Target | C5: Total Actual | D5: Variance | E5: Mortgage Target | F5: Actual | G5: Protection Target | H5: Actual | I5: Other Income Target | J5: Actual | K5: Written-to-Banked % | L5: Protection Pen % | M5: GI Pen % | N5: PED Retention %
A6: Jan | B6: ='Financial Plan'!D16 | D6: =IF(C6="","",C6-B6) | E6: ='Financial Plan'!D13 | G6: ='Financial Plan'!D14 | I6: ='Financial Plan'!D15
A7: Feb | B7: ='Financial Plan'!E16 | D7: =IF(C7="","",C7-B7) | E7: ='Financial Plan'!E13 | G7: ='Financial Plan'!E14 | I7: ='Financial Plan'!E15
A8: Mar | B8: ='Financial Plan'!F16 | D8: =IF(C8="","",C8-B8) | E8: ='Financial Plan'!F13 | G8: ='Financial Plan'!F14 | I8: ='Financial Plan'!F15
A9: Apr | B9: ='Financial Plan'!G16 | D9: =IF(C9="","",C9-B9) | E9: ='Financial Plan'!G13 | G9: ='Financial Plan'!G14 | I9: ='Financial Plan'!G15
A10: May | B10: ='Financial Plan'!H16 | D10: =IF(C10="","",C10-B10) | E10: ='Financial Plan'!H13 | G10: ='Financial Plan'!H14 | I10: ='Financial Plan'!H15
A11: Jun | B11: ='Financial Plan'!I16 | D11: =IF(C11="","",C11-B11) | E11: ='Financial Plan'!I13 | G11: ='Financial Plan'!I14 | I11: ='Financial Plan'!I15
A12: Jul | B12: ='Financial Plan'!J16 | D12: =IF(C12="","",C12-B12) | E12: ='Financial Plan'!J13 | G12: ='Financial Plan'!J14 | I12: ='Financial Plan'!J15
A13: Aug | B13: ='Financial Plan'!K16 | D13: =IF(C13="","",C13-B13) | E13: ='Financial Plan'!K13 | G13: ='Financial Plan'!K14 | I13: ='Financial Plan'!K15
A14: Sep | B14: ='Financial Plan'!L16 | D14: =IF(C14="","",C14-B14) | E14: ='Financial Plan'!L13 | G14: ='Financial Plan'!L14 | I14: ='Financial Plan'!L15
A15: Oct | B15: ='Financial Plan'!M16 | D15: =IF(C15="","",C15-B15) | E15: ='Financial Plan'!M13 | G15: ='Financial Plan'!M14 | I15: ='Financial Plan'!M15
A16: Nov | B16: ='Financial Plan'!N16 | D16: =IF(C16="","",C16-B16) | E16: ='Financial Plan'!N13 | G16: ='Financial Plan'!N14 | I16: ='Financial Plan'!N15
A17: Dec | B17: ='Financial Plan'!O16 | D17: =IF(C17="","",C17-B17) | E17: ='Financial Plan'!O13 | G17: ='Financial Plan'!O14 | I17: ='Financial Plan'!O15
A19: ANNUAL / AVERAGE | B19: =SUM(B6:B17) | C19: =SUM(C6:C17) | D19: =IF(C19=0,"",C19-B19) | E19: =SUM(E6:E17) | F19: =SUM(F6:F17) | G19: =SUM(G6:G17) | H19: =SUM(H6:H17) | I19: =SUM(I6:I17) | J19: =SUM(J6:J17) | K19: =IF(COUNTA(K6:K17)=0,"",AVERAGE(K6:K17)) | L19: =IF(COUNTA(L6:L17)=0,"",AVERAGE(L6:L17)) | M19: =IF(COUNTA(M6:M17)=0,"",AVERAGE(M6:M17)) | N19: =IF(COUNTA(N6:N17)=0,"",AVERAGE(N6:N17))

Sheet Risks & Actions
A1: Risks, Actions and Model Checks
A3: A single register for delivery actions, risks and dependencies.
A5: Model checks
A6: MODEL STATUS | B6: =IF(COUNTIF(B9:B12,"FAIL")=0,"PASS","FAIL")
A8: Check | B8: Status | C8: Delta | D8: Where to fix
A9: Annual target equals stream totals | B9: =IF(ABS(C9)<0.01,"PASS","FAIL") | C9: ='Financial Plan'!P16-SUM('Financial Plan'!P13:P15) | D9: Financial Plan
A10: Monthly totals equal annual | B10: =IF(ABS(C10)<0.01,"PASS","FAIL") | C10: =SUM('Financial Plan'!D16:O16)-'Financial Plan'!P16 | D10: Financial Plan
A11: Quarter total equals annual | B11: =IF(ABS(C11)<0.01,"PASS","FAIL") | C11: =SUM('Financial Plan'!B24:E24)-'Financial Plan'!F24 | D11: Financial Plan
A12: Plan year is 2027 | B12: =IF(ABS(C12)<0.01,"PASS","FAIL") | C12: =2027-2027 | D12: Financial Plan
A15: Risk and action register
A16: Risk / Action | B16: Type | C16: Likelihood | D16: Impact / Priority | E16: Mitigation / Next Step | F16: Owner | G16: Due Date | H16: Status | I16: Notes
A17: Rosemount appointment slips past end of September 2026 | B17: Risk | C17: High | D17: High | E17: Complete references, tests and due diligence immediately; keep Ahmed Bawa updated weekly. | F17: Bob / Rosemount (Ahmed Bawa) | G17: 46295 | H17: In Progress | I17: Exploratory meeting 2 Sep 2026. Own brand retained as trading style. Do not invent an FCA number.
A18: 12-month non-compete / redundancy terms still in negotiation | B18: Risk | C18: High | D18: High | E18: Solicitor Donald to conclude protected-conversation terms. Do not solicit Rettie clients. | F18: Donald (solicitor) / Bob | G18: 46326 | H18: In Progress | I18: Protected conversation August 2026. Pipeline not novated.
A19: No client bank — starting from zero | B19: Risk | C19: High | D19: High | E19: Activity-first first year. Convert introducers before relying on reviews or PED. | F19: Bob | G19: 46477 | H19: Open | I19: Rosemount: first year is hardest; be proactive on activity.
A20: Introducer concentration on DJ Alexander and Hannah Fraser | B20: Risk | C20: High | D20: High | E20: Put SLAs in writing. Add Ralph’s Thayer, accountants, website and BoE CRM so one source cannot stall the year. | F20: Bob | G20: 46387 | H20: In Progress | I20: Both named as primary. Volume still TBC on Business Overview.
A21: Glasgow exclusive agency unconfirmed — capacity / AR risk | B21: Risk | C21: Medium | D21: High | E21: Do not hire or move to AR until the exclusive is signed. Treat 2,000–3,000 homes/year as high-risk. | F21: Bob / DJ Alexander | G21: 46477 | H21: Open | I21: Would be enough for 3–4 advisers IF it lands. Not confirmed.
A22: Trading-style vs appointed-representative status | B22: Dependency | C22: Medium | D22: Medium | E22: Launch as trading style under Rosemount. Revisit AR only if advisers are recruited. | F22: Bob / Rosemount | G22: 46568 | H22: Open | I22: Ahmed Bawa: AR needed for Glasgow-scale volume.
A23: Onboarding references, tests and due diligence | B23: Action | C23: High | D23: High | E23: Diary the tests; chase references; complete the DD pack for end-September appointment. | F23: Bob | G23: 46295 | H23: In Progress | I23: Appointment possible end Sep 2026 subject to refs / tests / DD.
A24: International / overseas buyer advice rules not yet agreed | B24: Risk | C24: Medium | D24: High | E24: No international advice until Rosemount compliance confirms. Refer if needed. | F24: Bob / Rosemount compliance | G24: 46387 | H24: Open | I24: Edinburgh and St Andrews demand discussed; permissions still TBC.
A25: First-year cash is tight until introducers convert (2-month lag) | B25: Risk | C25: High | D25: High | E25: Hold a personal cash buffer. Overwrite Tesla and other yellow costs. Watch Monthly Costs net vs £80–120k. | F25: Bob | G25: 46477 | H25: Open | I25: Do not treat £240k protection written as monthly cash.
A26: Tesla Model Y lease amount unknown; company transfer needs lessor approval | B26: Risk | C26: Medium | D26: Medium | E26: Get the exact monthly from the lessor. Ask about assignment to a limited company before incorporating around the car. | F26: Bob | G26: 46326 | H26: Open | I26: 3 years remaining. Monthly Costs uses ~£550 estimate.
A27: Website build funding not secured | B27: Action | C27: Medium | D27: Medium | E27: Contact Business Gateway. Do not commit the ~£2,500 build until grant / funding is known. | F27: Bob | G27: 46326 | H27: Open | I27: Discussed 3 Sep 2026. Launch cost is on Monthly Costs as Estimate.
A28: Compliance bot / Tribe check not yet live | B28: Action | C28: Medium | D28: High | E28: Stand up the Tribe-document compliance Grokbot and switch on the automated Tribe check. | F28: Bob | G28: 46288 | H28: In Progress | I28: 26 Aug notes: reminder ~four weeks later (around 23 Sep 2026).
